Workbook

Sheet 91Days pre implementation data
A1: Date | B1: Daily_Reporting_Latency_Hours | C1: Operational_Phase | D1: Compliance_Status
A2: 46036 | B2: 1.25 | C2: Historical Baseline Run-Rate | D2: =IF(B2>$G$3,"NC","C") -> NC | F2: p50 | G2: =PERCENTILE(B2:B92,0.5) -> 1.14
A3: 46037 | B3: 1.16 | C3: Historical Baseline Run-Rate | D3: =IF(B3>$G$3,"NC","C") -> NC | F3: p25 | G3: =PERCENTILE(B2:B92,0.25) -> 1.005 | H3: target
A4: 46038 | B4: 1.28 | C4: Historical Baseline Run-Rate | D4: =IF(B4>$G$3,"NC","C") -> NC
A5: 46039 | B5: 1.41 | C5: Historical Baseline Run-Rate | D5: =IF(B5>$G$3,"NC","C") -> NC
A6: 46040 | B6: 1.14 | C6: Historical Baseline Run-Rate | D6: =IF(B6>$G$3,"NC","C") -> NC | F6: HISTORICAL DATA ANALYSIS | I6: INDUSTRY AVERAGE BENCHMARK | J6: WORLD-CLASS BENCHMARK
A7: 46041 | B7: 1.14 | C7: Historical Baseline Run-Rate | D7: =IF(B7>$G$3,"NC","C") -> NC | F7: NCs | G7: =COUNTIF(D2:D92,"NC") -> 68
A8: 46042 | B8: 1.42 | C8: Historical Baseline Run-Rate | D8: =IF(B8>$G$3,"NC","C") -> NC | F8: Total Days | G8: =COUNT(A2:A92) -> 91
A9: 46043 | B9: 1.3 | C9: Historical Baseline Run-Rate | D9: =IF(B9>$G$3,"NC","C") -> NC | F9: DPO | G9: =G7/G8 -> 0.74725275 | I9: 0.0500 (5.0%) | J9: < 0.00600 (0.6%)
A10: 46044 | B10: 1.11 | C10: Historical Baseline Run-Rate | D10: =IF(B10>$G$3,"NC","C") -> NC | F10: DPMO/PPM | G10: =G9*1000000 -> 747252.75 | I10: ≈ 50,000 | J10: < ,6000
A11: 46045 | B11: 1.26 | C11: Historical Baseline Run-Rate | D11: =IF(B11>$G$3,"NC","C") -> NC | F11: SIGMA SCORE 𝜎 | G11: =NORMSINV(1-G9) -> -0.66586952 | I11: `+2.00𝜎 to +3.00𝜎 | J11: > +4.5𝜎
A12: 46046 | B12: 1.11 | C12: Historical Baseline Run-Rate | D12: =IF(B12>$G$3,"NC","C") -> NC
A13: 46047 | B13: 1.11 | C13: Historical Baseline Run-Rate | D13: =IF(B13>$G$3,"NC","C") -> NC
A14: 46048 | B14: 1.22 | C14: Historical Baseline Run-Rate | D14: =IF(B14>$G$3,"NC","C") -> NC | F14: Goal
A15: 46049 | B15: 0.89 | C15: Historical Baseline Run-Rate | D15: =IF(B15>$G$3,"NC","C") -> C | F15: To reduce current median DRL from 1.14 to 1.005 by 3 months.
A16: 46050 | B16: 0.92 | C16: Historical Baseline Run-Rate | D16: =IF(B16>$G$3,"NC","C") -> C
A17: 46051 | B17: 1.1 | C17: Historical Baseline Run-Rate | D17: =IF(B17>$G$3,"NC","C") -> NC
A18: 46052 | B18: 1.03 | C18: Historical Baseline Run-Rate | D18: =IF(B18>$G$3,"NC","C") -> NC
A19: 46053 | B19: 1.23 | C19: Historical Baseline Run-Rate | D19: =IF(B19>$G$3,"NC","C") -> NC
A20: 46054 | B20: 1.04 | C20: Historical Baseline Run-Rate | D20: =IF(B20>$G$3,"NC","C") -> NC
A21: 46055 | B21: 0.97 | C21: Historical Baseline Run-Rate | D21: =IF(B21>$G$3,"NC","C") -> C
A22: 46056 | B22: 1.4 | C22: Historical Baseline Run-Rate | D22: =IF(B22>$G$3,"NC","C") -> NC
A23: 46057 | B23: 1.15 | C23: Historical Baseline Run-Rate | D23: =IF(B23>$G$3,"NC","C") -> NC
A24: 46058 | B24: 1.19 | C24: Historical Baseline Run-Rate | D24: =IF(B24>$G$3,"NC","C") -> NC | F24: Problem
A25: 46059 | B25: 0.97 | C25: Historical Baseline Run-Rate | D25: =IF(B25>$G$3,"NC","C") -> C | F25: There are 68 days out of 91 days, where performance is lower than statistical goal. i.e. NC = 74.72%; with DPMO value of 747252.7 and sigma score of -0.66587
A26: 46060 | B26: 1.1 | C26: Historical Baseline Run-Rate | D26: =IF(B26>$G$3,"NC","C") -> NC
A27: 46061 | B27: 1.2 | C27: Historical Baseline Run-Rate | D27: =IF(B27>$G$3,"NC","C") -> NC
A28: 46062 | B28: 1.01 | C28: Historical Baseline Run-Rate | D28: =IF(B28>$G$3,"NC","C") -> NC
A29: 46063 | B29: 1.24 | C29: Historical Baseline Run-Rate | D29: =IF(B29>$G$3,"NC","C") -> NC
A30: 46064 | B30: 1.09 | C30: Historical Baseline Run-Rate | D30: =IF(B30>$G$3,"NC","C") -> NC
A31: 46065 | B31: 1.14 | C31: Historical Baseline Run-Rate | D31: =IF(B31>$G$3,"NC","C") -> NC
A32: 46066 | B32: 1.09 | C32: Historical Baseline Run-Rate | D32: =IF(B32>$G$3,"NC","C") -> NC
A33: 46067 | B33: 1.46 | C33: Historical Baseline Run-Rate | D33: =IF(B33>$G$3,"NC","C") -> NC
A34: 46068 | B34: 1.18 | C34: Historical Baseline Run-Rate | D34: =IF(B34>$G$3,"NC","C") -> NC
A35: 46069 | B35: 1.02 | C35: Historical Baseline Run-Rate | D35: =IF(B35>$G$3,"NC","C") -> NC
A36: 46070 | B36: 1.3 | C36: Historical Baseline Run-Rate | D36: =IF(B36>$G$3,"NC","C") -> NC
A37: 46071 | B37: 1 | C37: Historical Baseline Run-Rate | D37: =IF(B37>$G$3,"NC","C") -> C
... A92: 46126 | B92: 0.03 | C92: Post-Implementation Control | D92: =IF(B92>$G$3,"NC","C") -> C

Sheet 50-50 Pre Post Data
A1: Date | B1: Daily_Reporting_Latency_Hours | C1: Operational_Phase | D1: Compliance_Status | E1: Implementation_Group
A2: ='91Days pre implementation data'!A35 -> 46069 | B2: ='91Days pre implementation data'!B35 -> 1.02 | C2: ='91Days pre implementation data'!C35 -> Historical Baseline Run-Rate | D2: ='91Days pre implementation data'!D35 -> NC | E2: ="Pre-Implementation" -> Pre-Implementation | G2: p50 | H2: =PERCENTILE(B2:B92,0.5) -> 0.4625
A3: ='91Days pre implementation data'!A36 -> 46070 | B3: ='91Days pre implementation data'!B36 -> 1.3 | C3: ='91Days pre implementation data'!C36 -> Historical Baseline Run-Rate | D3: ='91Days pre implementation data'!D36 -> NC | E3: ="Pre-Implementation" -> Pre-Implementation | G3: p25 | H3: =PERCENTILE(B2:B92,0.25) -> 0.029 | I3: target
A4: ='91Days pre implementation data'!A37 -> 46071 | B4: ='91Days pre implementation data'!B37 -> 1 | C4: ='91Days pre implementation data'!C37 -> Historical Baseline Run-Rate | D4: ='91Days pre implementation data'!D37 -> C | E4: ="Pre-Implementation" -> Pre-Implementation
A5: ='91Days pre implementation data'!A38 -> 46072 | B5: ='91Days pre implementation data'!B38 -> 1.21 | C5: ='91Days pre implementation data'!C38 -> Historical Baseline Run-Rate | D5: ='91Days pre implementation data'!D38 -> NC | E5: ="Pre-Implementation" -> Pre-Implementation
A6: ='91Days pre implementation data'!A39 -> 46073 | B6: ='91Days pre implementation data'!B39 -> 0.89 | C6: ='91Days pre implementation data'!C39 -> Historical Baseline Run-Rate | D6: ='91Days pre implementation data'!D39 -> C | E6: ="Pre-Implementation" -> Pre-Implementation | G6: HISTORICAL DATA ANALYSIS | J6: INDUSTRY AVERAGE BENCHMARK | K6: WORLD-CLASS BENCHMARK
A7: ='91Days pre implementation data'!A40 -> 46074 | B7: ='91Days pre implementation data'!B40 -> 0.98 | C7: ='91Days pre implementation data'!C40 -> Historical Baseline Run-Rate | D7: ='91Days pre implementation data'!D40 -> C | E7: ="Pre-Implementation" -> Pre-Implementation | G7: NCs | H7: =COUNTIF(D2:D92,"NC") -> 47
A8: ='91Days pre implementation data'!A41 -> 46075 | B8: ='91Days pre implementation data'!B41 -> 1.21 | C8: ='91Days pre implementation data'!C41 -> Historical Baseline Run-Rate | D8: ='91Days pre implementation data'!D41 -> NC | E8: ="Pre-Implementation" -> Pre-Implementation | G8: Total Days | H8: =COUNT(A2:A92) -> 90
A9: ='91Days pre implementation data'!A42 -> 46076 | B9: ='91Days pre implementation data'!B42 -> 1.29 | C9: ='91Days pre implementation data'!C42 -> Historical Baseline Run-Rate | D9: ='91Days pre implementation data'!D42 -> NC | E9: ="Pre-Implementation" -> Pre-Implementation | G9: DPO | H9: =H7/H8 -> 0.52222222 | J9: 0.0500 (5.0%) | K9: < 0.00600 (0.6%)
A10: ='91Days pre implementation data'!A43 -> 46077 | B10: ='91Days pre implementation data'!B43 -> 1.21 | C10: ='91Days pre implementation data'!C43 -> Historical Baseline Run-Rate | D10: ='91Days pre implementation data'!D43 -> NC | E10: ="Pre-Implementation" -> Pre-Implementation | G10: DPMO/PPM | H10: =H9*1000000 -> 522222.22 | J10: ≈ 50000 | K10: < 6000
A11: ='91Days pre implementation data'!A44 -> 46078 | B11: ='91Days pre implementation data'!B44 -> 1.16 | C11: ='91Days pre implementation data'!C44 -> Historical Baseline Run-Rate | D11: ='91Days pre implementation data'!D44 -> NC | E11: ="Pre-Implementation" -> Pre-Implementation | G11: SIGMA SCORE | H11: =NORMSINV(1-H9) -> -0.055731688 | J11: `+2.00𝜎 to +3.00𝜎 | K11: > +4.5𝜎
A12: ='91Days pre implementation data'!A45 -> 46079 | B12: ='91Days pre implementation data'!B45 -> 1.13 | C12: ='91Days pre implementation data'!C45 -> Historical Baseline Run-Rate | D12: ='91Days pre implementation data'!D45 -> NC | E12: ="Pre-Implementation" -> Pre-Implementation
A13: ='91Days pre implementation data'!A46 -> 46080 | B13: ='91Days pre implementation data'!B46 -> 0.96 | C13: ='91Days pre implementation data'!C46 -> Historical Baseline Run-Rate | D13: ='91Days pre implementation data'!D46 -> C | E13: ="Pre-Implementation" -> Pre-Implementation
A14: ='91Days pre implementation data'!A47 -> 46081 | B14: ='91Days pre implementation data'!B47 -> 1.07 | C14: ='91Days pre implementation data'!C47 -> Historical Baseline Run-Rate | D14: ='91Days pre implementation data'!D47 -> NC | E14: ="Pre-Implementation" -> Pre-Implementation | G14: Goal
A15: ='91Days pre implementation data'!A48 -> 46082 | B15: ='91Days pre implementation data'!B48 -> 1.11 | C15: ='91Days pre implementation data'!C48 -> Historical Baseline Run-Rate | D15: ='91Days pre implementation data'!D48 -> NC | E15: ="Pre-Implementation" -> Pre-Implementation | G15: To execute a leftward distribution shift in Daily Reporting Latency, reducing the process median from P50 = 0.4625 hours (27.75 minutes) to the demonstrated benchmark of P25 = 0.029 hours (1.74 minutes) within 3 months. The improvement will standardize demonstrated best performance as the new process midpoint, reduce latency variation, and progress the process toward zero latency defects and ≥6.00σ capability.
A16: ='91Days pre implementation data'!A49 -> 46083 | B16: ='91Days pre implementation data'!B49 -> 1.34 | C16: ='91Days pre implementation data'!C49 -> Historical Baseline Run-Rate | D16: ='91Days pre implementation data'!D49 -> NC | E16: ="Pre-Implementation" -> Pre-Implementation
A17: ='91Days pre implementation data'!A50 -> 46084 | B17: ='91Days pre implementation data'!B50 -> 1.23 | C17: ='91Days pre implementation data'!C50 -> Historical Baseline Run-Rate | D17: ='91Days pre implementation data'!D50 -> NC | E17: ="Pre-Implementation" -> Pre-Implementation
A18: ='91Days pre implementation data'!A51 -> 46085 | B18: ='91Days pre implementation data'!B51 -> 0.92 | C18: ='91Days pre implementation data'!C51 -> Historical Baseline Run-Rate | D18: ='91Days pre implementation data'!D51 -> C | E18: ="Pre-Implementation" -> Pre-Implementation
A19: ='91Days pre implementation data'!A52 -> 46086 | B19: ='91Days pre implementation data'!B52 -> 1.23 | C19: ='91Days pre implementation data'!C52 -> Historical Baseline Run-Rate | D19: ='91Days pre implementation data'!D52 -> NC | E19: ="Pre-Implementation" -> Pre-Implementation
A20: ='91Days pre implementation data'!A53 -> 46087 | B20: ='91Days pre implementation data'!B53 -> 1.12 | C20: ='91Days pre implementation data'!C53 -> Historical Baseline Run-Rate | D20: ='91Days pre implementation data'!D53 -> NC | E20: ="Pre-Implementation" -> Pre-Implementation
A21: ='91Days pre implementation data'!A54 -> 46088 | B21: ='91Days pre implementation data'!B54 -> 1.08 | C21: ='91Days pre implementation data'!C54 -> Historical Baseline Run-Rate | D21: ='91Days pre implementation data'!D54 -> NC | E21: ="Pre-Implementation" -> Pre-Implementation
A22: ='91Days pre implementation data'!A55 -> 46089 | B22: ='91Days pre implementation data'!B55 -> 1.27 | C22: ='91Days pre implementation data'!C55 -> Historical Baseline Run-Rate | D22: ='91Days pre implementation data'!D55 -> NC | E22: ="Pre-Implementation" -> Pre-Implementation
A23: ='91Days pre implementation data'!A56 -> 46090 | B23: ='91Days pre implementation data'!B56 -> 1.33 | C23: ='91Days pre implementation data'!C56 -> Historical Baseline Run-Rate | D23: ='91Days pre implementation data'!D56 -> NC | E23: ="Pre-Implementation" -> Pre-Implementation
A24: ='91Days pre implementation data'!A57 -> 46091 | B24: ='91Days pre implementation data'!B57 -> 1.32 | C24: ='91Days pre implementation data'!C57 -> Historical Baseline Run-Rate | D24: ='91Days pre implementation data'!D57 -> NC | E24: ="Pre-Implementation" -> Pre-Implementation | G24: Problem
A25: ='91Days pre implementation data'!A58 -> 46092 | B25: ='91Days pre implementation data'!B58 -> 1.05 | C25: ='91Days pre implementation data'!C58 -> Historical Baseline Run-Rate | D25: ='91Days pre implementation data'!D58 -> NC | E25: ="Pre-Implementation" -> Pre-Implementation | G25: The Daily Reporting Latency process has a current median of P50 = 0.4625 hours (27.75 minutes), compared with a demonstrated P25 benchmark of 0.029 hours (1.74 minutes). Across the 90-day evaluation period, 47 runs were classified as non-compliant, resulting in a 52.22% non-compliance rate, 522,222.22 DPMO, and a process sigma score of -0.0557σ. This performance remains significantly below the industry average benchmark of approximately 50,000 DPMO (+2.0σ to +3.0σ).
A26: ='91Days pre implementation data'!A59 -> 46093 | B26: ='91Days pre implementation data'!B59 -> 1.13 | C26: ='91Days pre implementation data'!C59 -> Historical Baseline Run-Rate | D26: ='91Days pre implementation data'!D59 -> NC | E26: ="Pre-Implementation" -> Pre-Implementation
A27: ='91Days pre implementation data'!A60 -> 46094 | B27: ='91Days pre implementation data'!B60 -> 1.23 | C27: ='91Days pre implementation data'!C60 -> Historical Baseline Run-Rate | D27: ='91Days pre implementation data'!D60 -> NC | E27: ="Pre-Implementation" -> Pre-Implementation
A28: ='91Days pre implementation data'!A61 -> 46095 | B28: ='91Days pre implementation data'!B61 -> 1.33 | C28: ='91Days pre implementation data'!C61 -> Historical Baseline Run-Rate | D28: ='91Days pre implementation data'!D61 -> NC | E28: ="Pre-Implementation" -> Pre-Implementation
A29: ='91Days pre implementation data'!A62 -> 46096 | B29: ='91Days pre implementation data'!B62 -> 1.11 | C29: ='91Days pre implementation data'!C62 -> Historical Baseline Run-Rate | D29: ='91Days pre implementation data'!D62 -> NC | E29: ="Pre-Implementation" -> Pre-Implementation
A30: ='91Days pre implementation data'!A63 -> 46097 | B30: ='91Days pre implementation data'!B63 -> 1.15 | C30: ='91Days pre implementation data'!C63 -> Historical Baseline Run-Rate | D30: ='91Days pre implementation data'!D63 -> NC | E30: ="Pre-Implementation" -> Pre-Implementation
A31: ='91Days pre implementation data'!A64 -> 46098 | B31: ='91Days pre implementation data'!B64 -> 1.01 | C31: ='91Days pre implementation data'!C64 -> Historical Baseline Run-Rate | D31: ='91Days pre implementation data'!D64 -> NC | E31: ="Pre-Implementation" -> Pre-Implementation
A32: ='91Days pre implementation data'!A65 -> 46099 | B32: ='91Days pre implementation data'!B65 -> 1 | C32: ='91Days pre implementation data'!C65 -> Historical Baseline Run-Rate | D32: ='91Days pre implementation data'!D65 -> C | E32: ="Pre-Implementation" -> Pre-Implementation
A33: ='91Days pre implementation data'!A66 -> 46100 | B33: ='91Days pre implementation data'!B66 -> 1.3 | C33: ='91Days pre implementation data'!C66 -> Historical Baseline Run-Rate | D33: ='91Days pre implementation data'!D66 -> NC | E33: ="Pre-Implementation" -> Pre-Implementation
A34: ='91Days pre implementation data'!A67 -> 46101 | B34: ='91Days pre implementation data'!B67 -> 1.38 | C34: ='91Days pre implementation data'!C67 -> Historical Baseline Run-Rate | D34: ='91Days pre implementation data'!D67 -> NC | E34: ="Pre-Implementation" -> Pre-Implementation
A35: ='91Days pre implementation data'!A68 -> 46102 | B35: ='91Days pre implementation data'!B68 -> 1.17 | C35: ='91Days pre implementation data'!C68 -> Historical Baseline Run-Rate | D35: ='91Days pre implementation data'!D68 -> NC | E35: ="Pre-Implementation" -> Pre-Implementation
A36: ='91Days pre implementation data'!A69 -> 46103 | B36: ='91Days pre implementation data'!B69 -> 1.33 | C36: ='91Days pre implementation data'!C69 -> Historical Baseline Run-Rate | D36: ='91Days pre implementation data'!D69 -> NC | E36: ="Pre-Implementation" -> Pre-Implementation
A37: ='91Days pre implementation data'!A70 -> 46104 | B37: ='91Days pre implementation data'!B70 -> 2.37 | C37: ='91Days pre implementation data'!C70 -> Pre-Implementation Crisis Spike | D37: ='91Days pre implementation data'!D70 -> NC | E37: ="Pre-Implementation" -> Pre-Implementation
... A46: ='91Days pre implementation data'!A79 -> 46113 | B46: ='91Days pre implementation data'!B79 -> 2.3 | C46: ='91Days pre implementation data'!C79 -> Pre-Implementation Crisis Spike | D46: ='91Days pre implementation data'!D79 -> NC | E46: ="Pre-Implementation" -> Pre-Implementation
A47: ='91Days post implementation data'!A2 -> 46114 | B47: ='91Days post implementation data'!B2 -> 0.035 | C47: ='91Days post implementation data'!C2 -> Post-Implementation Control (Go-Live) | D47: ='91Days post implementation data'!D2 -> NC | E47: ="Post-Implementation" -> Post-Implementation
A48: ='91Days post implementation data'!A3 -> 46115 | B48: ='91Days post implementation data'!B3 -> 0.023 | C48: ='91Days post implementation data'!C3 -> Post-Implementation Control | D48: ='91Days post implementation data'!D3 -> C | E48: ="Post-Implementation" -> Post-Implementation
...

Sheet 91Days post implementation data
A1: Date | B1: Daily_Reporting_Latency_Hours | C1: Operational_Phase | D1: Compliance_Status
A2: 46114 | B2: 0.035 | C2: Post-Implementation Control (Go-Live) | D2: =IF(B2>$G$3,"NC","C") -> NC | F2: p50 | G2: =PERCENTILE(B2:B92,0.5) -> 0.029
A3: 46115 | B3: 0.023 | C3: Post-Implementation Control | D3: =IF(B3>$G$3,"NC","C") -> C | F3: p25 | G3: =PERCENTILE(B2:B92,0.25) -> 0.029 | H3: target
A4: 46116 | B4: 0.029 | C4: Post-Implementation Control | D4: =IF(B4>$G$3,"NC","C") -> C
A5: 46117 | B5: 0.031 | C5: Post-Implementation Control | D5: =IF(B5>$G$3,"NC","C") -> NC
A6: 46118 | B6: 0.033 | C6: Post-Implementation Control | D6: =IF(B6>$G$3,"NC","C") -> NC | F6: HISTORICAL DATA ANALYSIS | I6: INDUSTRY AVERAGE BENCHMARK | J6: WORLD-CLASS BENCHMARK
A7: 46119 | B7: 0.027 | C7: Post-Implementation Control | D7: =IF(B7>$G$3,"NC","C") -> C | F7: NCs | G7: =COUNTIF(D2:D92,"NC") -> 8
A8: 46120 | B8: 0.028 | C8: Post-Implementation Control | D8: =IF(B8>$G$3,"NC","C") -> C | F8: Total Days | G8: =COUNT(A2:A92) -> 91
A9: 46121 | B9: 0.032 | C9: Post-Implementation Control | D9: =IF(B9>$G$3,"NC","C") -> NC | F9: DPO | G9: =G7/G8 -> 0.087912088 | I9: 0.0500 (5.0%) | J9: < 0.00600 (0.6%)
A10: 46122 | B10: 0.031 | C10: Post-Implementation Control | D10: =IF(B10>$G$3,"NC","C") -> NC | F10: DPMO/PPM | G10: =G9*1000000 -> 87912.088 | I10: ≈ 50,000 | J10: < 60,00
A11: 46123 | B11: 0.035 | C11: Post-Implementation Control | D11: =IF(B11>$G$3,"NC","C") -> NC | F11: SIGMA SCORE | G11: =NORMSINV(1-G9) -> 1.3537249 | I11: `+2.00𝜎 to +3.00𝜎 | J11: > +4.5𝜎
A12: 46124 | B12: 0.029 | C12: Post-Implementation Control | D12: =IF(B12>$G$3,"NC","C") -> C
A13: 46125 | B13: 0.034 | C13: Post-Implementation Control | D13: =IF(B13>$G$3,"NC","C") -> NC
A14: 46126 | B14: 0.03 | C14: Post-Implementation Control | D14: =IF(B14>$G$3,"NC","C") -> NC | F14: Goal
A15: 46127 | B15: 0.029 | C15: Post-Implementation Control | D15: =IF(B15>$G$3,"NC","C") -> C | F15: ="To sustain Daily Reporting Latency at P50 = "&TEXT(G2,"0.000")&" hours and P25 = "&TEXT(G3,"0.000")&" hours, while reducing non-compliant runs from "&G7&" to no more than 2 per 91-day control cycle. This will lower DPMO from "&TEXT(G10,"#,##0")&" to no more than 22,000 and raise process capability from "&TEXT(G11,"0.0000")&" sigma to at least 2.00 sigma as the next demonstrated performance threshold." -> To sustain Daily Reporting Latency at P50 = 0.029 hours and P25 = 0.029 hours, while reducing non-compliant runs from 8 to no more than 2 per 91-day control cycle. This will lower DPMO from 87,912 to no more than 22,000 and raise process capability from 1.3537 sigma to at least 2.00 sigma as the next demonstrated performance threshold.
A16: 46128 | B16: 0.029 | C16: Post-Implementation Control | D16: =IF(B16>$G$3,"NC","C") -> C
A17: 46129 | B17: 0.029 | C17: Post-Implementation Control | D17: =IF(B17>$G$3,"NC","C") -> C
A18: 46130 | B18: 0.029 | C18: Post-Implementation Control | D18: =IF(B18>$G$3,"NC","C") -> C
A19: 46131 | B19: 0.0286 | C19: Post-Implementation Control | D19: =IF(B19>$G$3,"NC","C") -> C
A20: 46132 | B20: 0.029 | C20: Post-Implementation Control | D20: =IF(B20>$G$3,"NC","C") -> C
A21: 46133 | B21: 0.029 | C21: Post-Implementation Control | D21: =IF(B21>$G$3,"NC","C") -> C
A22: 46134 | B22: 0.029 | C22: Post-Implementation Control | D22: =IF(B22>$G$3,"NC","C") -> C | F22: Improve Phase Focus
A23: 46135 | B23: 0.029 | C23: Post-Implementation Control | D23: =IF(B23>$G$3,"NC","C") -> C | F23: Preserve the achieved process center at P50 = 0.029 hours and P25 = 0.029 hours while reducing upper-tail variation. Investigate the 8 non-compliant runs for recurring timing, workload, source-system, and handoff causes; standardize the best-performing workflow; automate delay points; and add threshold alerts. Validate improvement over the next 91-day cycle by reducing NCs to no more than 2, DPMO to no more than 22,000, and raising sigma from 1.3537 to at least 2.00 before transition to Control.
A24: 46136 | B24: 0.029 | C24: Post-Implementation Control | D24: =IF(B24>$G$3,"NC","C") -> C
A25: 46137 | B25: 0.029 | C25: Post-Implementation Control | D25: =IF(B25>$G$3,"NC","C") -> C
A26: 46138 | B26: 0.0288 | C26: Post-Implementation Control | D26: =IF(B26>$G$3,"NC","C") -> C
A27: 46139 | B27: 0.029 | C27: Post-Implementation Control | D27: =IF(B27>$G$3,"NC","C") -> C
A28: 46140 | B28: 0.029 | C28: Post-Implementation Control | D28: =IF(B28>$G$3,"NC","C") -> C
A29: 46141 | B29: 0.029 | C29: Post-Implementation Control | D29: =IF(B29>$G$3,"NC","C") -> C
A30: 46142 | B30: 0.029 | C30: Post-Implementation Control | D30: =IF(B30>$G$3,"NC","C") -> C
A31: 46143 | B31: 0.029 | C31: Post-Implementation Control | D31: =IF(B31>$G$3,"NC","C") -> C
A32: 46144 | B32: 0.029 | C32: Post-Implementation Control | D32: =IF(B32>$G$3,"NC","C") -> C
A33: 46145 | B33: 0.029 | C33: Post-Implementation Control | D33: =IF(B33>$G$3,"NC","C") -> C
A34: 46146 | B34: 0.0284 | C34: Post-Implementation Control | D34: =IF(B34>$G$3,"NC","C") -> C
A35: 46147 | B35: 0.029 | C35: Post-Implementation Control | D35: =IF(B35>$G$3,"NC","C") -> C
... A92: 46204 | B92: 0.029 | C92: Post-Implementation Control (Current) | D92: =IF(B92>$G$3,"NC","C") -> C
